Workbook

Sheet Сводка
B2: СВОДКА — главное одним экраном
B4: ТЕКУЩИЙ СЦЕНАРИЙ (живое: пересчитывается при правке «Допущений»)
B5: Выбран сценарий (1=Пессимист, 2=База, 3=Целевой) | C5: =Допущения!$D$2
B6: Клиентов к декабрю 2027 | C6: =Воронка!S13
B7: Выручка за 2027 | C7: =Воронка!U18
B8: Операционный результат за 2027 | C8: =Воронка!U25
B9: Месяцев в минусе (из 17) | C9: =COUNTIF(Воронка!C25:S25,"<0")
B10: Дно кассы (самая глубокая яма) | C10: =MIN(Воронка!C28:S28)
B11: НУЖНО ДЕНЕГ сверх плана 3 млн | C11: =MAX(0,-MIN(Воронка!C28:S28))
B12: Касса на конец 2027 | C12: =Воронка!S28
B14: ТРИ СЦЕНАРИЯ РЯДОМ (снимок при допущениях от 03.07.2026 — после правок сверяйся с живым блоком выше)
B15: Сценарий | C15: Клиентов дек-27 | D15: Результат/мес в конце 27 | E15: Первый плюсовой месяц | F15: Нужно сверх 3 млн
B16: Пессимист | C16: 27 | D16: −751 тыс. | E16: никогда | F16: 13,6 млн
B17: База (историч. цифры) | C17: 75 | D17: −474 тыс. | E17: никогда | F17: 10,5 млн
B18: Целевой (все рычаги) | C18: 241 | D18: +359 тыс. | E18: март 2027 | F18: 3,6 млн
B20: РЫЧАГИ: «База» + один рычаг за раз (что двигает результат)
B21: Вариант | C21: Клиентов дек-27 | D21: Результат/мес | E21: Нужно сверх 3 млн
B22: База как есть | C22: 75 | D22: −474 тыс. | E22: 10,5 млн
B23: + продления как у когорт-2026 (3 покупки) | C23: 106 | D23: −317 тыс. | E23: 8,9 млн
B24: + органика 50 лидов/мес (потолок 100) | C24: 103 | D24: −297 тыс. | E24: 7,9 млн
B25: + конверсия платного 15% | C25: 80 | D25: −445 тыс. | E25: 10,1 млн
B26: + таргет 200 лидов/мес | C26: 110 | D26: −322 тыс. | E26: 8,4 млн
B27: ПРОДЛЕНИЯ + ОРГАНИКА (таргет не трогаем) | C27: 150 | D27: −77 тыс. | E27: 5,6 млн
B28: Все рычаги вместе | C28: 218 | D28: +211 тыс. | E28: 2,9 млн
B30: ЧТО УТОЧНИТЬ, ЧТОБЫ ЦИФРЫ СТАЛИ ТВЁРДЫМИ (сейчас — заглушки, жёлтое на «Допущениях»)
B31: ПОДТВЕРЖДЕНО (июль-2026): открытие 1–5 августа · достройка ≈1,7 млн · тренеры 500 ₽/группа + 100 ₽/ребёнок
B32: 1. Продления 82–94% у когорт-2026 — правда или формат оплаты (администратор) — рычаг №1
B33: 2. Органика: сколько лидов/мес бесплатно приходит сейчас — рычаг №2
B34: 3. Таргетолог: максимум лидов/мес и на каком бюджете
B35: 4. Старт с нуля или с переносом части базы действующего центра
B36: 5. Какая CRM куплена за 103 тыс/год
B37: 6. Финансирование: капекс уже больше плана — сколько денег реально доступно и когда?
B39: ВЫВОДЫ: капекс 3,25 млн (потрачено 1,55 + достройка 1,7) УЖЕ больше плана 3,0 — касса в минусе ещё до открытия.
B40: ТБ ≈ 185–190 клиентов. «База» бездонна (−11,2 млн к дек-2027). Путь в плюс = продления + сарафан + чек; целевой: плюс с марта 2027.
B41: Разговор о деньгах — не «до октября», а сейчас: без ещё ~3,5 млн подтверждённых даже лучший план умирает в сентябре.

Sheet Допущения
B2: Активный сценарий (1=Пессимист, 2=База, 3=Целевой): | D2: 2 | H2: Меняешь одну цифру — пересчитывается вся модель. 3 = «к чему стремиться».
B4: Параметр | C4: ед. | D4: АКТИВНОЕ | E4: Пессимист | F4: База | G4: Целевой | H4: Комментарий / источник
B5: — ВОРОНКА —
B6: CPL — цена сырого лида (таргет) | C6: ₽ | D6: =INDEX(E6:G6,$D$2) | E6: 1000 | F6: 800 | G6: 1200 | H6: ФАКТ из кабинета ВК (окт-25→май-26, 403 заявки): средний 780 ₽, коридор 700–1100. Целевой дороже: +30% CPL на каждое удвоение объёма.
B7: Конверсия платного лида в покупку | C7: % | D7: =INDEX(E7:G7,$D$2) | E7: 0.1 | F7: 0.13 | G7: 0.15 | H7: Факт CRM: VK 13% (n=1039). >15% на чисто платном не бывает.
B8: Конверсия органического лида в покупку | C8: % | D8: =INDEX(E8:G8,$D$2) | E8: 0.2 | F8: 0.25 | G8: 0.25 | H8: Факт CRM: сайт/органика 25–27% (n=400).
B9: Потолок платных лидов | C9: шт/мес | D9: =INDEX(E9:G9,$D$2) | E9: 70 | F9: 100 | G9: 200 | H9: ФАКТ: 30–50/мес на бюджете 30–45т; пик 127 (янв, бюджет 73т, без роста CPL). Выше 130 — экстраполяция = ГЛАВНЫЙ РИСК модели.
B10: Органические лиды на старте (сарафан/карты/сайт) | C10: шт/мес | D10: =INDEX(E10:G10,$D$2) | E10: 10 | F10: 20 | G10: 30 | H10: ЗАГЛУШКА — ждём факт действующего центра.
B11: Рост органики | C11: %/мес | D11: =INDEX(E11:G11,$D$2) | E11: 0.05 | F11: 0.08 | G11: 0.12 | H11: ЗАГЛУШКА — реф.программа «привёл друга» (бот) должна разгонять.
B12: Доля лидов, дошедших до пробного | C12: % | D12: =INDEX(E12:G12,$D$2) | E12: 0.35 | F12: 0.5 | G12: 0.55 | H12: Ваша оценка: ~50%. Для выручки пробных (900 ₽).
B13: Коэфф. «зачислен → оплатил» | D13: =INDEX(E13:G13,$D$2) | E13: 0.93 | F13: 0.93 | G13: 0.93 | H13: Факт CRM: 7% зачисленных не платят.
B14: — ПРОДУКТ И ДЕНЬГИ —
B15: Средний платёж (один абонемент) | C15: ₽ | D15: =INDEX(E15:G15,$D$2) | E15: 9000 | F15: 9800 | G15: 10500 | H15: По новому прайсу, микс 70% одно напр. / 20% единый / 10% индив.
B16: Средняя длительность абонемента | C16: мес | D16: =INDEX(E16:G16,$D$2) | E16: 1.7 | F16: 1.7 | G16: 1.7 | H16: Микс 1-мес и 2-мес абонементов.
B17: Покупок на клиента за жизнь | C17: шт | D17: =INDEX(E17:G17,$D$2) | E17: 1.8 | F17: 2 | G17: 3 | H17: Факт CRM: ~2 (продление 40–49% до 2-й, ~20% до 3-й). Целевой 3 = когорты 2026 (82–94%) — проверить у администратора!
B18: Цена пробного | C18: ₽ | D18: =INDEX(E18:G18,$D$2) | E18: 900 | F18: 900 | G18: 900 | H18: Некупившие платят 900; у купивших зачтено в абонемент.
B19: Вместимость: действующих абонементов макс | C19: шт | D19: =INDEX(E19:G19,$D$2) | E19: 250 | F19: 250 | G19: 250 | H19: Слово собственницы: потолок загрузки 250.
B20: Стартовая база клиентов (перенос из действующего центра) | C20: чел | D20: =INDEX(E20:G20,$D$2) | E20: 0 | F20: 0 | G20: 0 | H20: ОТКРЫТЫЙ ВОПРОС: старт с нуля или с переносом?
B21: — РАСХОДЫ (разбивка ФОТ — слова собственницы, июль-2026) —
B22: Прочие постоянные расходы | C22: ₽/мес | D22: =INDEX(E22:G22,$D$2) | E22: 435000 | F22: 435000 | G22: 435000 | H22: Из исходника: аренда 360 + РКО 10 + 1С 15 + канц 10 + мотив 30 + связь 10.
B23: ФОТ фикс-ядро (маркетинг 130 + админы 120 + руковод. 100) | C23: ₽/мес | D23: =INDEX(E23:G23,$D$2) | E23: 350000 | F23: 350000 | G23: 350000 | H23: Платится независимо от числа клиентов — это якорь точки безубыточности.
B24: Ставка тренера за группу (даже пустую) | C24: ₽ | D24: =INDEX(E24:G24,$D$2) | E24: 500 | F24: 500 | G24: 500 | H24: ФАКТ (июль-2026): 500 ₽ за занятие группы, платится даже если никто не пришёл.
B25: Ставка тренера за ребёнка | C25: ₽ | D25: =INDEX(E25:G25,$D$2) | E25: 100 | F25: 100 | G25: 100 | H25: ФАКТ: +100 ₽ за каждого пришедшего ребёнка (посещений ≈ 4,33/мес на клиента).
B26: Мин. сетка групп в неделю (стартовое расписание) | C26: шт | D26: =INDEX(E26:G26,$D$2) | E26: 24 | F26: 30 | G26: 30 | H26: Пустые группы тоже стоят 500 ₽ → floor тренерского ФОТ ≈ 52–65 тыс/мес.
B27: Средняя наполняемость группы | C27: чел | D27: =INDEX(E27:G27,$D$2) | E27: 3.5 | F27: 4 | G27: 4.5 | H27: Макс 6 пар; при полном зале тренеры ≈ 244 тыс/мес — бюджет собственницы (250) сходится.
B28: — ДЕНЬГИ СОБСТВЕННИЦЫ —
B29: План финансирования всего | C29: ₽ | D29: =INDEX(E29:G29,$D$2) | E29: 3000000 | F29: 3000000 | G29: 3000000 | H29: Слова собственницы: «рассчитывала на 3 млн» (ремонт + оборудование + первый маркетинг).
B30: Уже потрачено до открытия (факт на 03.07.2026) | C30: ₽ | D30: =INDEX(E30:G30,$D$2) | E30: 1551733 | F30: 1551733 | G30: 1551733 | H30: По списку оплат: ремонт 719,3к · оборудование 303,2к · ИТ/маркетинг 275к · дизайн-проекты 252к · прочее 2,2к.
B31: Достройка до открытия (остаток ремонта и оборудования) | C31: ₽ | D31: =INDEX(E31:G31,$D$2) | E31: 1700000 | F31: 1700000 | G31: 1700000 | H31: ФАКТ (июль-2026): ≈1,7 млн, падает в август. Вместе с потраченными 1,55 млн капекс = 3,25 млн > плана 3,0 млн.
B33: — РАСЧЁТНЫЕ (не трогать) —
B34: Жизнь клиента (= покупок × длительность) | C34: мес | D34: =D17*D16
B35: Деньги с действующего клиента в месяц (= платёж / длительность) | C35: ₽/мес | D35: =D15/D16
B36: Бюджет таргета (= потолок лидов × CPL) | C36: ₽/мес | D36: =D9*D6
B37: Касса на старте (= план 3 млн − уже потрачено) | C37: ₽ | D37: =D29-D30
B39: — СЕЗОННОСТЬ (факт вашей CRM; можно править) —
B40: Месяц | C40: Коэфф. притока лидов | D40: Коэфф. конверсии в покупку
B41: январь | C41: 1 | D41: 0.6
B42: февраль | C42: 1.4 | D42: 1
B43: март | C43: 1.1 | D43: 1
B44: апрель | C44: 1 | D44: 1
...

Sheet Воронка
B2: Воронка и деньги (всё считается с листа «Допущения»)
B3: Месяц | C3: 46235 | D3: 46266 | E3: 46296 | F3: 46327 | G3: 46357 | H3: 46388 | I3: 46419 | J3: 46447 | K3: 46478 | L3: 46508 | M3: 46539 | N3: 46569 | O3: 46600 | P3: 46631 | Q3: 46661 | R3: 46692 | S3: 46722 | T3: 2026 | U3: 2027
B5: Сезонный коэфф. притока | C5: =INDEX(Допущения!$C$41:$C$52,MONTH(C$3)) | D5: =INDEX(Допущения!$C$41:$C$52,MONTH(D$3)) | E5: =INDEX(Допущения!$C$41:$C$52,MONTH(E$3)) | F5: =INDEX(Допущения!$C$41:$C$52,MONTH(F$3)) | G5: =INDEX(Допущения!$C$41:$C$52,MONTH(G$3)) | H5: =INDEX(Допущения!$C$41:$C$52,MONTH(H$3)) | I5: =INDEX(Допущения!$C$41:$C$52,MONTH(I$3)) | J5: =INDEX(Допущения!$C$41:$C$52,MONTH(J$3)) | ... S5: =INDEX(Допущения!$C$41:$C$52,MONTH(S$3))
B6: Сезонный коэфф. конверсии | C6: =INDEX(Допущения!$D$41:$D$52,MONTH(C$3)) | D6: =INDEX(Допущения!$D$41:$D$52,MONTH(D$3)) | E6: =INDEX(Допущения!$D$41:$D$52,MONTH(E$3)) | F6: =INDEX(Допущения!$D$41:$D$52,MONTH(F$3)) | G6: =INDEX(Допущения!$D$41:$D$52,MONTH(G$3)) | H6: =INDEX(Допущения!$D$41:$D$52,MONTH(H$3)) | I6: =INDEX(Допущения!$D$41:$D$52,MONTH(I$3)) | J6: =INDEX(Допущения!$D$41:$D$52,MONTH(J$3)) | ... S6: =INDEX(Допущения!$D$41:$D$52,MONTH(S$3))
B8: Платные лиды (таргет, с потолком канала) | C8: =MIN(Допущения!$D$9,Допущения!$D$36/Допущения!$D$6)*C5 | D8: =MIN(Допущения!$D$9,Допущения!$D$36/Допущения!$D$6)*D5 | E8: =MIN(Допущения!$D$9,Допущения!$D$36/Допущения!$D$6)*E5 | F8: =MIN(Допущения!$D$9,Допущения!$D$36/Допущения!$D$6)*F5 | G8: =MIN(Допущения!$D$9,Допущения!$D$36/Допущения!$D$6)*G5 | H8: =MIN(Допущения!$D$9,Допущения!$D$36/Допущения!$D$6)*H5 | I8: =MIN(Допущения!$D$9,Допущения!$D$36/Допущения!$D$6)*I5 | J8: =MIN(Допущения!$D$9,Допущения!$D$36/Допущения!$D$6)*J5 | ... S8: =MIN(Допущения!$D$9,Допущения!$D$36/Допущения!$D$6)*S5 | T8: =SUM(C8:G8) | U8: =SUM(H8:S8)
B9: Органические лиды (сарафан/карты/сайт) | C9: =Допущения!$D$10*(1+Допущения!$D$11)^0*C5 | D9: =Допущения!$D$10*(1+Допущения!$D$11)^1*D5 | E9: =Допущения!$D$10*(1+Допущения!$D$11)^2*E5 | F9: =Допущения!$D$10*(1+Допущения!$D$11)^3*F5 | G9: =Допущения!$D$10*(1+Допущения!$D$11)^4*G5 | H9: =Допущения!$D$10*(1+Допущения!$D$11)^5*H5 | I9: =Допущения!$D$10*(1+Допущения!$D$11)^6*I5 | J9: =Допущения!$D$10*(1+Допущения!$D$11)^7*J5 | K9: =Допущения!$D$10*(1+Допущения!$D$11)^8*K5 | L9: =Допущения!$D$10*(1+Допущения!$D$11)^9*L5 | M9: =Допущения!$D$10*(1+Допущения!$D$11)^10*M5 | N9: =Допущения!$D$10*(1+Допущения!$D$11)^11*N5 | O9: =Допущения!$D$10*(1+Допущения!$D$11)^12*O5 | P9: =Допущения!$D$10*(1+Допущения!$D$11)^13*P5 | Q9: =Допущения!$D$10*(1+Допущения!$D$11)^14*Q5 | R9: =Допущения!$D$10*(1+Допущения!$D$11)^15*R5 | S9: =Допущения!$D$10*(1+Допущения!$D$11)^16*S5 | T9: =SUM(C9:G9) | U9: =SUM(H9:S9)
B10: Лидов всего | C10: =C8+C9 | D10: =D8+D9 | E10: =E8+E9 | F10: =F8+F9 | G10: =G8+G9 | H10: =H8+H9 | I10: =I8+I9 | J10: =J8+J9 | ... S10: =S8+S9 | T10: =SUM(C10:G10) | U10: =SUM(H10:S10)
B11: Пробных занятий | C11: =(C8+C9)*Допущения!$D$12*C6 | D11: =(D8+D9)*Допущения!$D$12*D6 | E11: =(E8+E9)*Допущения!$D$12*E6 | F11: =(F8+F9)*Допущения!$D$12*F6 | G11: =(G8+G9)*Допущения!$D$12*G6 | H11: =(H8+H9)*Допущения!$D$12*H6 | I11: =(I8+I9)*Допущения!$D$12*I6 | J11: =(J8+J9)*Допущения!$D$12*J6 | ... S11: =(S8+S9)*Допущения!$D$12*S6 | T11: =SUM(C11:G11) | U11: =SUM(H11:S11)
B12: НОВЫХ клиентов (купили абонемент) | C12: =(C8*Допущения!$D$7+C9*Допущения!$D$8)*C6*Допущения!$D$13 | D12: =(D8*Допущения!$D$7+D9*Допущения!$D$8)*D6*Допущения!$D$13 | E12: =(E8*Допущения!$D$7+E9*Допущения!$D$8)*E6*Допущения!$D$13 | F12: =(F8*Допущения!$D$7+F9*Допущения!$D$8)*F6*Допущения!$D$13 | G12: =(G8*Допущения!$D$7+G9*Допущения!$D$8)*G6*Допущения!$D$13 | H12: =(H8*Допущения!$D$7+H9*Допущения!$D$8)*H6*Допущения!$D$13 | I12: =(I8*Допущения!$D$7+I9*Допущения!$D$8)*I6*Допущения!$D$13 | J12: =(J8*Допущения!$D$7+J9*Допущения!$D$8)*J6*Допущения!$D$13 | ... S12: =(S8*Допущения!$D$7+S9*Допущения!$D$8)*S6*Допущения!$D$13 | T12: =SUM(C12:G12) | U12: =SUM(H12:S12)
B13: ДЕЙСТВУЮЩИХ клиентов (абонементы) | C13: =MIN(Допущения!$D$19,Допущения!$D$20*(1-1/Допущения!$D$34)+C12) | D13: =MIN(Допущения!$D$19,C13*(1-1/Допущения!$D$34)+D12) | E13: =MIN(Допущения!$D$19,D13*(1-1/Допущения!$D$34)+E12) | F13: =MIN(Допущения!$D$19,E13*(1-1/Допущения!$D$34)+F12) | G13: =MIN(Допущения!$D$19,F13*(1-1/Допущения!$D$34)+G12) | H13: =MIN(Допущения!$D$19,G13*(1-1/Допущения!$D$34)+H12) | I13: =MIN(Допущения!$D$19,H13*(1-1/Допущения!$D$34)+I12) | J13: =MIN(Допущения!$D$19,I13*(1-1/Допущения!$D$34)+J12) | K13: =MIN(Допущения!$D$19,J13*(1-1/Допущения!$D$34)+K12) | ... S13: =MIN(Допущения!$D$19,R13*(1-1/Допущения!$D$34)+S12)
B14: Загрузка от потолка 250 | C14: =C13/Допущения!$D$19 | D14: =D13/Допущения!$D$19 | E14: =E13/Допущения!$D$19 | F14: =F13/Допущения!$D$19 | G14: =G13/Допущения!$D$19 | H14: =H13/Допущения!$D$19 | I14: =I13/Допущения!$D$19 | J14: =J13/Допущения!$D$19 | ... S14: =S13/Допущения!$D$19
B16: Выручка: абонементы | C16: =C13*Допущения!$D$35 | D16: =D13*Допущения!$D$35 | E16: =E13*Допущения!$D$35 | F16: =F13*Допущения!$D$35 | G16: =G13*Допущения!$D$35 | H16: =H13*Допущения!$D$35 | I16: =I13*Допущения!$D$35 | J16: =J13*Допущения!$D$35 | ... S16: =S13*Допущения!$D$35 | T16: =SUM(C16:G16) | U16: =SUM(H16:S16)
B17: Выручка: пробные (некупившие) | C17: =MAX(0,C11-C12)*Допущения!$D$18 | D17: =MAX(0,D11-D12)*Допущения!$D$18 | E17: =MAX(0,E11-E12)*Допущения!$D$18 | F17: =MAX(0,F11-F12)*Допущения!$D$18 | G17: =MAX(0,G11-G12)*Допущения!$D$18 | H17: =MAX(0,H11-H12)*Допущения!$D$18 | I17: =MAX(0,I11-I12)*Допущения!$D$18 | J17: =MAX(0,J11-J12)*Допущения!$D$18 | ... S17: =MAX(0,S11-S12)*Допущения!$D$18 | T17: =SUM(C17:G17) | U17: =SUM(H17:S17)
B18: ИТОГО выручка | C18: =C16+C17 | D18: =D16+D17 | E18: =E16+E17 | F18: =F16+F17 | G18: =G16+G17 | H18: =H16+H17 | I18: =I16+I17 | J18: =J16+J17 | ... S18: =S16+S17 | T18: =SUM(C18:G18) | U18: =SUM(H18:S18)
B20: Маркетинг (таргет) | C20: =Допущения!$D$36 | D20: =Допущения!$D$36 | E20: =Допущения!$D$36 | F20: =Допущения!$D$36 | G20: =Допущения!$D$36 | H20: =Допущения!$D$36 | I20: =Допущения!$D$36 | J20: =Допущения!$D$36 | ... S20: =Допущения!$D$36 | T20: =SUM(C20:G20) | U20: =SUM(H20:S20)
B21: Прочие постоянные (аренда и т.п.) | C21: =Допущения!$D$22 | D21: =Допущения!$D$22 | E21: =Допущения!$D$22 | F21: =Допущения!$D$22 | G21: =Допущения!$D$22 | H21: =Допущения!$D$22 | I21: =Допущения!$D$22 | J21: =Допущения!$D$22 | ... S21: =Допущения!$D$22 | T21: =SUM(C21:G21) | U21: =SUM(H21:S21)
B22: ФОТ фикс-ядро (маркетинг+админы+руковод.) | C22: =Допущения!$D$23 | D22: =Допущения!$D$23 | E22: =Допущения!$D$23 | F22: =Допущения!$D$23 | G22: =Допущения!$D$23 | H22: =Допущения!$D$23 | I22: =Допущения!$D$23 | J22: =Допущения!$D$23 | ... S22: =Допущения!$D$23 | T22: =SUM(C22:G22) | U22: =SUM(H22:S22)
B23: ФОТ преподаватели (500/группа + 100/ребёнок) | C23: =MAX(Допущения!$D$26,C13/Допущения!$D$27)*4.33*Допущения!$D$24+C13*4.33*Допущения!$D$25 | D23: =MAX(Допущения!$D$26,D13/Допущения!$D$27)*4.33*Допущения!$D$24+D13*4.33*Допущения!$D$25 | E23: =MAX(Допущения!$D$26,E13/Допущения!$D$27)*4.33*Допущения!$D$24+E13*4.33*Допущения!$D$25 | F23: =MAX(Допущения!$D$26,F13/Допущения!$D$27)*4.33*Допущения!$D$24+F13*4.33*Допущения!$D$25 | G23: =MAX(Допущения!$D$26,G13/Допущения!$D$27)*4.33*Допущения!$D$24+G13*4.33*Допущения!$D$25 | H23: =MAX(Допущения!$D$26,H13/Допущения!$D$27)*4.33*Допущения!$D$24+H13*4.33*Допущения!$D$25 | I23: =MAX(Допущения!$D$26,I13/Допущения!$D$27)*4.33*Допущения!$D$24+I13*4.33*Допущения!$D$25 | J23: =MAX(Допущения!$D$26,J13/Допущения!$D$27)*4.33*Допущения!$D$24+J13*4.33*Допущения!$D$25 | ... S23: =MAX(Допущения!$D$26,S13/Допущения!$D$27)*4.33*Допущения!$D$24+S13*4.33*Допущения!$D$25 | T23: =SUM(C23:G23) | U23: =SUM(H23:S23)
B24: Налоги (ровно как в исходнике!) | C24: 38260 | D24: 0 | E24: 0 | F24: 0 | G24: 40000 | H24: 0 | I24: 0 | J24: 0 | K24: 0 | L24: 0 | M24: 0 | N24: 0 | O24: 0 | P24: 0 | Q24: 0 | R24: 0 | S24: 0 | T24: ⚠ 2027 в исходнике не было: УСН/взносы не заложены | U24: =SUM(H24:S24)
B25: ОПЕРАЦИОННЫЙ РЕЗУЛЬТАТ (месяц) | C25: =C18-C20-C21-C22-C23-C24 | D25: =D18-D20-D21-D22-D23-D24 | E25: =E18-E20-E21-E22-E23-E24 | F25: =F18-F20-F21-F22-F23-F24 | G25: =G18-G20-G21-G22-G23-G24 | H25: =H18-H20-H21-H22-H23-H24 | I25: =I18-I20-I21-I22-I23-I24 | J25: =J18-J20-J21-J22-J23-J24 | ... S25: =S18-S20-S21-S22-S23-S24 | T25: =SUM(C25:G25) | U25: =SUM(H25:S25)
B27: Достройка до открытия (капекс, август) | C27: =Допущения!$D$31 | D27: =0 | E27: =0 | F27: =0 | G27: =0 | H27: =0 | I27: =0 | J27: =0 | K27: =0 | ... S27: =0 | T27: =SUM(C27:G27) | U27: =SUM(H27:S27)
B28: КАССА на конец месяца | C28: =Допущения!$D$37+C25-C27 | D28: =C28+D25-D27 | E28: =D28+E25-E27 | F28: =E28+F25-F27 | G28: =F28+G25-G27 | H28: =G28+H25-H27 | I28: =H28+I25-I27 | J28: =I28+J25-J27 | K28: =J28+K25-K27 | ... S28: =R28+S25-S27

Sheet Читайка
B2: КАК ПОЛЬЗОВАТЬСЯ
B3: 1. Лист «Допущения», ячейка D2: переключи сценарий 1/2/3 — вся модель пересчитается.
B4: 2. Синие ячейки — можно править. Жёлтые строки — заглушки, ждём реальные данные.
B5: 3. Лист «Воронка»: главные строки — ДЕЙСТВУЮЩИХ клиентов, ИТОГО выручка, ОПЕРАЦИОННЫЙ РЕЗУЛЬТАТ.
B7: ЧТО ЭТО ЗА ЭТАП
B8: Это ГОТОВАЯ рабочая версия (этапы 1–4): сводка + воронка + деньги. ФОТ разнесён (фикс-ядро 350к + преподаватели по загрузке),
B9: заведены деньги собственницы (план 3 млн, потрачено 1 551 733) и строка «КАССА на конец месяца» —
B10: красная заливка = деньги кончились. Налоги — ровно как в исходнике (2027 пустой — там налогов не было!).
B11: Этап 4: сводка сценариев — сколько всего нужно денег, когда ноль, когда окупаемость.
B13: ЧЕГО НЕ ХВАТАЕТ (жёлтые места)
B14: Подтверждено (июль-2026): открытие 1–5 августа; достройка ≈1,7 млн; тренеры 500 ₽/группа + 100 ₽/ребёнок.
B15: — Органика: сколько лидов/мес сейчас без рекламы (сарафан/карты/сайт)
... B18: — «Нежданчик» — вводные для прогноза
